<?xml version="1.0" encoding="utf-8"?>
<!-- This URDF was automatically created by SolidWorks to URDF Exporter! Originally created by Stephen Brawner (brawner@gmail.com) 
     Commit Version: 1.6.0-4-g7f85cfe  Build Version: 1.6.7995.38578
     For more information, please see http://wiki.ros.org/sw_urdf_exporter -->
<robot
  name="hermes_robot">
  <link
    name="base_link">
    <inertial>
      <origin
        xyz="-2.10371551824301E-07 -6.02315454494495E-08 0.0435789551996021"
        rpy="0 0 0" />
      <mass
        value="5.7729702362968" />
      <inertia
        ixx="0.0261442345766528"
        ixy="2.82877608896773E-06"
        ixz="7.47544587441788E-10"
        iyy="0.0219026044240062"
        iyz="1.64489628951597E-09"
        izz="0.0462053263639469" />
    </inertial>
    <visual>
      <origin
        xyz="0 0 0"
        rpy="0 0 0" />
      <geometry>
        <mesh
          filename="/Robots/hermes_robot/meshes/base_link.STL" />
      </geometry>
      <material
        name="">
        <color
          rgba="0 0 0 1"/>
      </material>
    </visual>
    <collision>
      <origin
        xyz="0 0 0"
        rpy="0 0 0" />
      <geometry>
        <mesh
          filename="/Robots/hermes_robot/meshes/base_link.STL" />
      </geometry>
    </collision>
  </link>
  <link
    name="Revolve1">
    <inertial>
      <origin
        xyz="-0.0020315725347394 -3.32570022357204E-06 -0.146515511784745"
        rpy="0 0 0" />
      <mass
        value="0.269968020345209" />
      <inertia
        ixx="0.000817081008544825"
        ixy="1.43755452488272E-06"
        ixz="5.94712654176722E-08"
        iyy="0.000962909407158131"
        iyz="1.19067342375234E-06"
        izz="0.000432508914878456" />
    </inertial>
    <visual>
      <origin
        xyz="0 0 0"
        rpy="0 0 0" />
      <geometry>
        <mesh
          filename="/Robots/hermes_robot/meshes/Revolve1.STL" />
      </geometry>
      <material
        name="">
        <color
          rgba="0 0 0 1"/>
      </material>
    </visual>
    <collision>
      <origin
        xyz="0 0 0"
        rpy="0 0 0" />
      <geometry>
        <mesh
          filename="/Robots/hermes_robot/meshes/Revolve1.STL" />
      </geometry>
    </collision>
  </link>
  <joint
    name="Joint_Revolve1"
    type="continuous">
    <origin
      xyz="0.14293 0.16281 0.080887"
      rpy="0 0 0" />
    <parent
      link="base_link" />
    <child
      link="Revolve1" />
    <axis
      xyz="0 0 -1" />
    <limit
      lower="0"
      upper="6.28"
      effort="0"
      velocity="0" />
  </joint>
  <link
    name="Drive1">
    <inertial>
      <origin
        xyz="-0.0595900865520644 0.0010304557549595 0.000120396514376758"
        rpy="0 0 0" />
      <mass
        value="0.968781681350828" />
      <inertia
        ixx="0.00433308692834699"
        ixy="-1.99069564081488E-05"
        ixz="1.18928999633502E-07"
        iyy="0.0023145060676988"
        iyz="-8.1287126219861E-08"
        izz="0.00231372917988357" />
    </inertial>
    <visual>
      <origin
        xyz="0 0 0"
        rpy="0 0 0" />
      <geometry>
        <mesh
          filename="/Robots/hermes_robot/meshes/Drive1.STL" />
      </geometry>
      <material
        name="">
        <color
          rgba="0 0 0 1"/>
      </material>
    </visual>
    <collision>
      <origin
        xyz="0 0 0"
        rpy="0 0 0" />
      <geometry>
        <mesh
          filename="/Robots/hermes_robot/meshes/Drive1.STL" />
      </geometry>
    </collision>
  </link>
  <joint
    name="Joint_Drive1"
    type="continuous">
    <origin
      xyz="0.058211 -0.00088915 -0.23708"
      rpy="0 0 0" />
    <parent
      link="Revolve1" />
    <child
      link="Drive1" />
    <axis
      xyz="-0.99995 0.0098663 0" />
    <limit
      lower="0"
      upper="0"
      effort="0"
      velocity="10" />
  </joint>
  <link
    name="Revolve2">
    <inertial>
      <origin
        xyz="0.00369562604088616 9.94372754585526E-05 -0.14554695452501"
        rpy="0 0 0" />
      <mass
        value="0.278169943270248" />
      <inertia
        ixx="0.000818393002551493"
        ixy="1.09066203211809E-06"
        ixz="-4.70925775867913E-08"
        iyy="0.000964158396336433"
        iyz="8.33032522006963E-08"
        izz="0.000433636015059847" />
    </inertial>
    <visual>
      <origin
        xyz="0 0 0"
        rpy="0 0 0" />
      <geometry>
        <mesh
          filename="/Robots/hermes_robot/meshes/Revolve2.STL" />
      </geometry>
      <material
        name="">
        <color
          rgba="0 0 0 1"/>
      </material>
    </visual>
    <collision>
      <origin
        xyz="0 0 0"
        rpy="0 0 0" />
      <geometry>
        <mesh
          filename="/Robots/hermes_robot/meshes/Revolve2.STL" />
      </geometry>
    </collision>
  </link>
  <joint
    name="Joint_Revolve2"
    type="continuous">
    <origin
      xyz="0.14237 -0.16281 0.080887"
      rpy="0 0 0" />
    <parent
      link="base_link" />
    <child
      link="Revolve2" />
    <axis
      xyz="0 0 -1" />
    <limit
      lower="0"
      upper="6.28"
      effort="0"
      velocity="0" />
  </joint>
  <link
    name="Drive2">
    <inertial>
      <origin
        xyz="-0.0604042669261472 1.00490558338773E-05 0.000120396499160874"
        rpy="0 0 0" />
      <mass
        value="0.968781685280355" />
      <inertia
        ixx="0.00433317009545422"
        ixy="-1.5113061042615E-05"
        ixz="-1.19121259096089E-07"
        iyy="0.00231442290382322"
        iyz="8.10046961048803E-08"
        izz="0.00231372918105276" />
    </inertial>
    <visual>
      <origin
        xyz="0 0 0"
        rpy="0 0 0" />
      <geometry>
        <mesh
          filename="/Robots/hermes_robot/meshes/Drive2.STL" />
      </geometry>
      <material
        name="">
        <color
          rgba="0 0 0 1"/>
      </material>
    </visual>
    <collision>
      <origin
        xyz="0 0 0"
        rpy="0 0 0" />
      <geometry>
        <mesh
          filename="/Robots/hermes_robot/meshes/Drive2.STL" />
      </geometry>
    </collision>
  </link>
  <joint
    name="Joint_Drive2"
    type="continuous">
    <origin
      xyz="0.061783 -0.00014808 -0.23708"
      rpy="0 0 0" />
    <parent
      link="Revolve2" />
    <child
      link="Drive2" />
    <axis
      xyz="0.99997 -0.0074916 0" />
    <limit
      lower="0"
      upper="0"
      effort="0"
      velocity="10" />
  </joint>
  <link
    name="Revolve3">
    <inertial>
      <origin
        xyz="-0.145078348740284 0.000298251578032982 -0.00416216736019684"
        rpy="0 0 0" />
      <mass
        value="0.282156111545984" />
      <inertia
        ixx="0.000434125726646059"
        ixy="2.26740392878552E-06"
        ixz="2.46147953844453E-08"
        iyy="0.000964214819932214"
        iyz="-1.47963647126562E-06"
        izz="0.000818912285874929" />
    </inertial>
    <visual>
      <origin
        xyz="0 0 0"
        rpy="0 0 0" />
      <geometry>
        <mesh
          filename="/Robots/hermes_robot/meshes/Revolve3.STL" />
      </geometry>
      <material
        name="">
        <color
          rgba="0 0 0 1"/>
      </material>
    </visual>
    <collision>
      <origin
        xyz="0 0 0"
        rpy="0 0 0" />
      <geometry>
        <mesh
          filename="/Robots/hermes_robot/meshes/Revolve3.STL" />
      </geometry>
    </collision>
  </link>
  <joint
    name="Joint_Revolve3"
    type="continuous">
    <origin
      xyz="-0.14293 -0.16281 0.080887"
      rpy="3.1416 -1.5708 0" />
    <parent
      link="base_link" />
    <child
      link="Revolve3" />
    <axis
      xyz="-1 0 0" />
    <limit
      lower="0"
      upper="6.28"
      effort="0"
      velocity="0" />
  </joint>
  <link
    name="Drive3">
    <inertial>
      <origin
        xyz="0.000120396516468307 0.000173138811222162 0.0604040196046097"
        rpy="0 0 0" />
      <mass
        value="0.968781680813743" />
      <inertia
        ixx="0.00231372917972381"
        ixy="8.13257654302086E-08"
        ixz="1.18902620179094E-07"
        iyy="0.00231451922820414"
        iyz="2.05633802827397E-05"
        izz="0.00433307376740016" />
    </inertial>
    <visual>
      <origin
        xyz="0 0 0"
        rpy="0 0 0" />
      <geometry>
        <mesh
          filename="/Robots/hermes_robot/meshes/Drive3.STL" />
      </geometry>
      <material
        name="">
        <color
          rgba="0 0 0 1"/>
      </material>
    </visual>
    <collision>
      <origin
        xyz="0 0 0"
        rpy="0 0 0" />
      <geometry>
        <mesh
          filename="/Robots/hermes_robot/meshes/Drive3.STL" />
      </geometry>
    </collision>
  </link>
  <joint
    name="Joint_Drive3"
    type="continuous">
    <origin
      xyz="-0.23708 -0.0003149 -0.061783"
      rpy="0 0 0" />
    <parent
      link="Revolve3" />
    <child
      link="Drive3" />
    <axis
      xyz="0 -0.010191 -0.99995" />
    <limit
      lower="0"
      upper="0"
      effort="0"
      velocity="10" />
  </joint>
  <link
    name="Revolve4">
    <inertial>
      <origin
        xyz="-0.00369447983778581 -5.57141729282673E-05 -0.145545341192344"
        rpy="0 0 0" />
      <mass
        value="0.278169949354846" />
      <inertia
        ixx="0.000818395728366805"
        ixy="-1.00119769955693E-06"
        ixz="4.24905936671552E-08"
        iyy="0.000964130017408439"
        iyz="8.97615065711788E-07"
        izz="0.000433670847908861" />
    </inertial>
    <visual>
      <origin
        xyz="0 0 0"
        rpy="0 0 0" />
      <geometry>
        <mesh
          filename="/Robots/hermes_robot/meshes/Revolve4.STL" />
      </geometry>
      <material
        name="">
        <color
          rgba="0 0 0 1"/>
      </material>
    </visual>
    <collision>
      <origin
        xyz="0 0 0"
        rpy="0 0 0" />
      <geometry>
        <mesh
          filename="/Robots/hermes_robot/meshes/Revolve4.STL" />
      </geometry>
    </collision>
  </link>
  <joint
    name="Joint_Revolve4"
    type="continuous">
    <origin
      xyz="-0.14237 0.16281 0.080887"
      rpy="0 0 0" />
    <parent
      link="base_link" />
    <child
      link="Revolve4" />
    <axis
      xyz="0 0 -1" />
    <limit
      lower="0"
      upper="6.28"
      effort="0"
      velocity="0" />
  </joint>
  <link
    name="Drive4">
    <inertial>
      <origin
        xyz="-0.0622112205431669 4.79255844373916E-06 0.000114732036940984"
        rpy="0 0 0" />
      <mass
        value="0.850687527986548" />
      <inertia
        ixx="0.00415798393864943"
        ixy="1.31982957892877E-05"
        ixz="7.75917649710273E-08"
        iyy="0.00221684368675788"
        iyz="-2.1169487140673E-07"
        izz="0.00221655869094813" />
    </inertial>
    <visual>
      <origin
        xyz="0 0 0"
        rpy="0 0 0" />
      <geometry>
        <mesh
          filename="/Robots/hermes_robot/meshes/Drive4.STL" />
      </geometry>
      <material
        name="">
        <color
          rgba="0 0 0 1"/>
      </material>
    </visual>
    <collision>
      <origin
        xyz="0 0 0"
        rpy="0 0 0" />
      <geometry>
        <mesh
          filename="/Robots/hermes_robot/meshes/Drive4.STL" />
      </geometry>
    </collision>
  </link>
  <joint
    name="Joint_Drive4"
    type="continuous">
    <origin
      xyz="0.058218 8.492E-05 -0.23708"
      rpy="0 0 0" />
    <parent
      link="Revolve4" />
    <child
      link="Drive4" />
    <axis
      xyz="-0.99998 -0.0068655 0" />
    <limit
      lower="0"
      upper="0"
      effort="0"
      velocity="10" />
  </joint>
</robot>