<?xml version="1.0" encoding="utf-8"?>
<!-- This URDF was automatically created by SolidWorks to URDF Exporter! Originally created by Stephen Brawner (brawner@gmail.com) 
     Commit Version: 1.6.0-4-g7f85cfe  Build Version: 1.6.7995.38578
     For more information, please see http://wiki.ros.org/sw_urdf_exporter -->
<robot
  name="hermes_robot">
  <link
    name="base_link">
    <inertial>
      <origin
        xyz="-0.000556181803337466 0.000570937752360604 0.0435789551996021"
        rpy="0 0 0" />
      <mass
        value="5.7729702362968" />
      <inertia
        ixx="0.0261442275560952"
        ixy="2.83374260607611E-06"
        ixz="3.54056280145004E-10"
        iyy="0.0219026114445638"
        iyz="-3.69571892989752E-09"
        izz="0.0462053263639469" />
    </inertial>
    <visual>
      <origin
        xyz="0 0 0"
        rpy="0 0 0" />
      <geometry>
        <mesh
          filename="package://hermes_robot/meshes/base_link.STL" />
      </geometry>
      <material
        name="">
        <color
          rgba="0.792156862745098 0.819607843137255 0.933333333333333 1" />
      </material>
    </visual>
    <collision>
      <origin
        xyz="0 0 0"
        rpy="0 0 0" />
      <geometry>
        <mesh
          filename="package://hermes_robot/meshes/base_link.STL" />
      </geometry>
    </collision>
  </link>
  <link
    name="Drive1">
    <inertial>
      <origin
        xyz="-0.1420725891101 -0.162134622350807 -0.156070154760362"
        rpy="0 0 0" />
      <mass
        value="0.968782085796601" />
      <inertia
        ixx="0.00424819090788287"
        ixy="0.000405658975873631"
        ixz="-1.33753498051603E-07"
        iyy="0.00239940264366684"
        iyz="5.40490091912558E-08"
        izz="0.00231372951894429" />
    </inertial>
    <visual>
      <origin
        xyz="0 0 0"
        rpy="0 0 0" />
      <geometry>
        <mesh
          filename="package://hermes_robot/meshes/Drive1.STL" />
      </geometry>
      <material
        name="">
        <color
          rgba="0.792156862745098 0.819607843137255 0.933333333333333 1" />
      </material>
    </visual>
    <collision>
      <origin
        xyz="0 0 0"
        rpy="0 0 0" />
      <geometry>
        <mesh
          filename="package://hermes_robot/meshes/Drive1.STL" />
      </geometry>
    </collision>
  </link>
  <joint
    name="Drive1"
    type="continuous">
    <origin
      xyz="0 0 0"
      rpy="0 0 0" />
    <parent
      link="base_link" />
    <child
      link="Drive1" />
    <axis
      xyz="0.97870110149261 0.205290413651375 0" />
    <limit
      lower="0"
      upper="0"
      effort="0"
      velocity="0" />
  </joint>
  <link
    name="Revolve1">
    <inertial>
      <origin
        xyz="-0.141466084457788 -0.161853031131481 -0.0656290075223259"
        rpy="0 0 0" />
      <mass
        value="0.269967968577388" />
      <inertia
        ixx="0.000823214345411263"
        ixy="-2.93067371662363E-05"
        ixz="1.97986047317922E-07"
        iyy="0.000956776012547063"
        iyz="-1.17541609043327E-06"
        izz="0.000432509071635242" />
    </inertial>
    <visual>
      <origin
        xyz="0 0 0"
        rpy="0 0 0" />
      <geometry>
        <mesh
          filename="package://hermes_robot/meshes/Revolve1.STL" />
      </geometry>
      <material
        name="">
        <color
          rgba="0.792156862745098 0.819607843137255 0.933333333333333 1" />
      </material>
    </visual>
    <collision>
      <origin
        xyz="0 0 0"
        rpy="0 0 0" />
      <geometry>
        <mesh
          filename="package://hermes_robot/meshes/Revolve1.STL" />
      </geometry>
    </collision>
  </link>
  <joint
    name="Revolve1"
    type="continuous">
    <origin
      xyz="0 0 0"
      rpy="0 0 0" />
    <parent
      link="base_link" />
    <child
      link="Revolve1" />
    <axis
      xyz="0 0 -1" />
    <limit
      lower="0"
      upper="0"
      effort="0"
      velocity="0" />
  </joint>
  <link
    name="Drive2">
    <inertial>
      <origin
        xyz="-0.144304789295268 0.1635100096225 -0.156070146198233"
        rpy="0 0 0" />
      <mass
        value="0.968781690098536" />
      <inertia
        ixx="0.00433324470774927"
        ixy="8.81932849506355E-06"
        ixz="1.20072511760892E-07"
        iyy="0.00231434829506239"
        iyz="-7.95880198649092E-08"
        izz="0.00231372918275736" />
    </inertial>
    <visual>
      <origin
        xyz="0 0 0"
        rpy="0 0 0" />
      <geometry>
        <mesh
          filename="package://hermes_robot/meshes/Drive2.STL" />
      </geometry>
      <material
        name="">
        <color
          rgba="0.792156862745098 0.819607843137255 0.933333333333333 1" />
      </material>
    </visual>
    <collision>
      <origin
        xyz="0 0 0"
        rpy="0 0 0" />
      <geometry>
        <mesh
          filename="package://hermes_robot/meshes/Drive2.STL" />
      </geometry>
    </collision>
  </link>
  <joint
    name="Drive2"
    type="continuous">
    <origin
      xyz="0 0 0"
      rpy="0 0 0" />
    <parent
      link="base_link" />
    <child
      link="Drive2" />
    <axis
      xyz="-0.99999 -0.0043624 0" />
    <limit
      lower="0"
      upper="0"
      effort="0"
      velocity="0" />
  </joint>
  <link
    name="Revolve2">
    <inertial>
      <origin
        xyz="-0.146618377379889 0.163245089096765 -0.0646604351303308"
        rpy="0 0 0" />
      <mass
        value="0.278169948732177" />
      <inertia
        ixx="0.0008183916496691"
        ixy="-6.36538680400576E-07"
        ixz="4.90295921045357E-08"
        iyy="0.000964166932349003"
        iyz="-8.45617137522346E-08"
        izz="0.000433638035486262" />
    </inertial>
    <visual>
      <origin
        xyz="0 0 0"
        rpy="0 0 0" />
      <geometry>
        <mesh
          filename="package://hermes_robot/meshes/Revolve2.STL" />
      </geometry>
      <material
        name="">
        <color
          rgba="0.792156862745098 0.819607843137255 0.933333333333333 1" />
      </material>
    </visual>
    <collision>
      <origin
        xyz="0 0 0"
        rpy="0 0 0" />
      <geometry>
        <mesh
          filename="package://hermes_robot/meshes/Revolve2.STL" />
      </geometry>
    </collision>
  </link>
  <joint
    name="Revolve2"
    type="continuous">
    <origin
      xyz="0 0 0"
      rpy="0 0 0" />
    <parent
      link="base_link" />
    <child
      link="Revolve2" />
    <axis
      xyz="0 0 -1" />
    <limit
      lower="0"
      upper="0"
      effort="0"
      velocity="0" />
  </joint>
  <link
    name="Drive3">
    <inertial>
      <origin
        xyz="0.140993840623201 0.163504687420311 -0.156070146224578"
        rpy="0 0 0" />
      <mass
        value="0.968781681639634" />
      <inertia
        ixx="0.00433311198628059"
        ixy="1.85931348598485E-05"
        ixz="1.20457318091981E-07"
        iyy="0.00231448100908392"
        iyz="-7.90061289408879E-08"
        izz="0.00231372918054459" />
    </inertial>
    <visual>
      <origin
        xyz="0 0 0"
        rpy="0 0 0" />
      <geometry>
        <mesh
          filename="package://hermes_robot/meshes/Drive3.STL" />
      </geometry>
      <material
        name="">
        <color
          rgba="0.792156862745098 0.819607843137255 0.933333333333333 1" />
      </material>
    </visual>
    <collision>
      <origin
        xyz="0 0 0"
        rpy="0 0 0" />
      <geometry>
        <mesh
          filename="package://hermes_robot/meshes/Drive3.STL" />
      </geometry>
    </collision>
  </link>
  <joint
    name="Drive3"
    type="continuous">
    <origin
      xyz="0 0 0"
      rpy="0 0 0" />
    <parent
      link="base_link" />
    <child
      link="Drive3" />
    <axis
      xyz="-0.99996 -0.0092037 0" />
    <limit
      lower="0"
      upper="0"
      effort="0"
      velocity="0" />
  </joint>
  <link
    name="Revolve3">
    <inertial>
      <origin
        xyz="0.138219414091918 0.163010768557002 -0.0641918308498002"
        rpy="0 0 0" />
      <mass
        value="0.282156119775798" />
      <inertia
        ixx="0.00081891351595226"
        ixy="-1.33814106792158E-06"
        ixz="6.95245348361614E-08"
        iyy="0.000964220705516278"
        iyz="-2.26832453723831E-06"
        izz="0.00043412775603021" />
    </inertial>
    <visual>
      <origin
        xyz="0 0 0"
        rpy="0 0 0" />
      <geometry>
        <mesh
          filename="package://hermes_robot/meshes/Revolve3.STL" />
      </geometry>
      <material
        name="">
        <color
          rgba="0.792156862745098 0.819607843137255 0.933333333333333 1" />
      </material>
    </visual>
    <collision>
      <origin
        xyz="0 0 0"
        rpy="0 0 0" />
      <geometry>
        <mesh
          filename="package://hermes_robot/meshes/Revolve3.STL" />
      </geometry>
    </collision>
  </link>
  <joint
    name="Revolve3"
    type="continuous">
    <origin
      xyz="0 0 0"
      rpy="0 0 0" />
    <parent
      link="base_link" />
    <child
      link="Revolve3" />
    <axis
      xyz="0 0 -1" />
    <limit
      lower="0"
      upper="0"
      effort="0"
      velocity="0" />
  </joint>
  <link
    name="Drive4">
    <inertial>
      <origin
        xyz="0.145813876266853 -0.162036451776305 -0.15607581163648"
        rpy="0 0 0" />
      <mass
        value="0.850687457270781" />
      <inertia
        ixx="0.00414382740979683"
        ixy="0.00016569087872877"
        ixz="-9.40592748834482E-08"
        iyy="0.00223100012543131"
        iyz="2.04937027287629E-07"
        izz="0.00221655864206811" />
    </inertial>
    <visual>
      <origin
        xyz="0 0 0"
        rpy="0 0 0" />
      <geometry>
        <mesh
          filename="package://hermes_robot/meshes/Drive4.STL" />
      </geometry>
      <material
        name="">
        <color
          rgba="0.792156862745098 0.819607843137255 0.933333333333333 1" />
      </material>
    </visual>
    <collision>
      <origin
        xyz="0 0 0"
        rpy="0 0 0" />
      <geometry>
        <mesh
          filename="package://hermes_robot/meshes/Drive4.STL" />
      </geometry>
    </collision>
  </link>
  <joint
    name="Drive4"
    type="continuous">
    <origin
      xyz="0 0 0"
      rpy="0 0 0" />
    <parent
      link="base_link" />
    <child
      link="Drive4" />
    <axis
      xyz="0.99632 0.085731 0" />
    <limit
      lower="0"
      upper="0"
      effort="0"
      velocity="0" />
  </joint>
  <link
    name="Revolve4">
    <inertial>
      <origin
        xyz="0.145504672682003 -0.161915015271395 -0.0646588276523701"
        rpy="0 0 0" />
      <mass
        value="0.278169965817926" />
      <inertia
        ixx="0.000819456084899018"
        ixy="-1.24507806840137E-05"
        ixz="2.97097230639296E-08"
        iyy="0.000963062288932822"
        iyz="-8.99752464071538E-07"
        izz="0.000433668966726285" />
    </inertial>
    <visual>
      <origin
        xyz="0 0 0"
        rpy="0 0 0" />
      <geometry>
        <mesh
          filename="package://hermes_robot/meshes/Revolve4.STL" />
      </geometry>
      <material
        name="">
        <color
          rgba="0.792156862745098 0.819607843137255 0.933333333333333 1" />
      </material>
    </visual>
    <collision>
      <origin
        xyz="0 0 0"
        rpy="0 0 0" />
      <geometry>
        <mesh
          filename="package://hermes_robot/meshes/Revolve4.STL" />
      </geometry>
    </collision>
  </link>
  <joint
    name="Revolve4"
    type="continuous">
    <origin
      xyz="0 0 0"
      rpy="0 0 0" />
    <parent
      link="base_link" />
    <child
      link="Revolve4" />
    <axis
      xyz="0 0 -1" />
    <limit
      lower="0"
      upper="0"
      effort="0"
      velocity="0" />
  </joint>
</robot>