<sdf version='1.11'>
  <model name='hermes_robot_description'>
    <link name='base_footprint'>
      <inertial>
        <pose>-1.8042111179182801e-05 0.0026809477953682798 0.043756141209230402 0 0 0</pose>
        <mass>5.8359407947604698</mass>
        <inertia>
          <ixx>0.0262319829443243</ixx>
          <ixy>2.75289714906734e-06</ixy>
          <ixz>1.561067669060765e-09</ixz>
          <iyy>0.022106705951238901</iyy>
          <iyz>1.5287951021228029e-09</iyz>
          <izz>0.046325188086441899</izz>
        </inertia>
      </inertial>
      <collision name='base_footprint_fixed_joint_lump__base_link_collision'>
        <pose>0 0 0 0 0 0</pose>
        <geometry>
          <mesh>
            <scale>1 1 1</scale>
            <uri>model://hermes_robot_description/meshes/base_link.STL</uri>
          </mesh>
        </geometry>
      </collision>
      <visual name='base_footprint_fixed_joint_lump__base_link_visual'>
        <pose>0 0 0 0 0 0</pose>
        <geometry>
          <mesh>
            <scale>1 1 1</scale>
            <uri>model://hermes_robot_description/meshes/base_link.STL</uri>
          </mesh>
        </geometry>
        <material>
          <diffuse>0.990196109 1 1 1</diffuse>
          <ambient>0.990196109 1 1 1</ambient>
        </material>
      </visual>
    </link>
    <joint name='Camera_pivot_joint' type='revolute'>
      <pose relative_to='base_footprint'>0.0543500000000001 0.23015000000000099 0.060000000000000303 1.5707963267949003 0 0</pose>
      <parent>base_footprint</parent>
      <child>Camera_pivot</child>
      <axis>
        <xyz>1 0 0</xyz>
        <limit>
          <lower>0</lower>
          <upper>0</upper>
          <effort>20</effort>
          <velocity>10</velocity>
        </limit>
        <dynamics>
          <spring_reference>0</spring_reference>
          <spring_stiffness>0</spring_stiffness>
        </dynamics>
      </axis>
    </joint>
    <link name='Camera_pivot'>
      <pose relative_to='Camera_pivot_joint'>0 0 0 0 0 0</pose>
      <inertial>
        <pose>-0.055592846981772567 0.00042034172012227851 -0.0032859047150442071 0 0 0</pose>
        <mass>1.2890901191943109</mass>
        <inertia>
          <ixx>0.0001178238839926729</ixx>
          <ixy>-1.4998478874677159e-06</ixy>
          <ixz>1.125981229121165e-05</ixz>
          <iyy>0.00079572499828658733</iyy>
          <iyz>7.8692840212091749e-07</iyz>
          <izz>0.00078853055747875062</izz>
        </inertia>
      </inertial>
      <collision name='Camera_pivot_collision'>
        <pose>0 0 0 0 0 0</pose>
        <geometry>
          <mesh>
            <scale>1 1 1</scale>
            <uri>model://hermes_robot_description/meshes/Camera_pivot.STL</uri>
          </mesh>
        </geometry>
      </collision>
      <collision name='Camera_pivot_fixed_joint_lump__CameraVision_collision_1'>
        <pose>-0.054499999999999597 0.0023070163905073398 -0.016858882862572599 3.14159265358979 0 3.14159265358979</pose>
        <geometry>
          <mesh>
            <scale>1 1 1</scale>
            <uri>model://hermes_robot_description/meshes/CameraVision.STL</uri>
          </mesh>
        </geometry>
      </collision>
      <visual name='Camera_pivot_visual'>
        <pose>0 0 0 0 0 0</pose>
        <geometry>
          <mesh>
            <scale>1 1 1</scale>
            <uri>model://hermes_robot_description/meshes/Camera_pivot.STL</uri>
          </mesh>
        </geometry>
        <material>
          <diffuse>0.990196109 1 1 1</diffuse>
          <ambient>0.990196109 1 1 1</ambient>
        </material>
      </visual>
      <visual name='Camera_pivot_fixed_joint_lump__CameraVision_visual_1'>
        <pose>-0.054499999999999597 0.0023070163905073398 -0.016858882862572599 3.14159265358979 0 3.14159265358979</pose>
        <geometry>
          <mesh>
            <scale>1 1 1</scale>
            <uri>model://hermes_robot_description/meshes/CameraVision.STL</uri>
          </mesh>
        </geometry>
        <material>
          <diffuse>0.990196109 1 1 1</diffuse>
          <ambient>0.990196109 1 1 1</ambient>
        </material>
      </visual>
    </link>
    <joint name='Joint_Revolve1' type='revolute'>
      <pose relative_to='base_footprint'>0.142812746894597 0.162367298941792 0.080886521716679996 0 0 0</pose>
      <parent>base_footprint</parent>
      <child>Revolve1</child>
      <axis>
        <xyz>0 0 1</xyz>
        <limit>
          <effort>50</effort>
          <velocity>20</velocity>
          <lower>-inf</lower>
          <upper>inf</upper>
        </limit>
        <dynamics>
          <spring_reference>0</spring_reference>
          <spring_stiffness>0</spring_stiffness>
        </dynamics>
      </axis>
    </joint>
    <link name='Revolve1'>
      <pose relative_to='Joint_Revolve1'>0 0 0 0 0 0</pose>
      <inertial>
        <pose>-0.000145935398461222 0.0033039815284095198 -0.129360241681652 0 0 0</pose>
        <mass>0.36061573342591102</mass>
        <inertia>
          <ixx>0.00101198014035825</ixx>
          <ixy>5.7583154827766401e-10</ixy>
          <ixz>-3.1290995103311602e-07</ixz>
          <iyy>0.00086643890432831696</iyy>
          <iyz>-4.8674095279480503e-08</iyz>
          <izz>0.00049820792238695899</izz>
        </inertia>
      </inertial>
      <collision name='Revolve1_collision'>
        <pose>0 0 0 0 0 0</pose>
        <geometry>
          <mesh>
            <scale>1 1 1</scale>
            <uri>model://hermes_robot_description/meshes/Revolve1.STL</uri>
          </mesh>
        </geometry>
      </collision>
      <visual name='Revolve1_visual'>
        <pose>0 0 0 0 0 0</pose>
        <geometry>
          <mesh>
            <scale>1 1 1</scale>
            <uri>model://hermes_robot_description/meshes/Revolve1.STL</uri>
          </mesh>
        </geometry>
        <material>
          <diffuse>0.990196109 1 1 1</diffuse>
          <ambient>0.990196109 1 1 1</ambient>
        </material>
      </visual>
    </link>
    <joint name='Joint_Drive1' type='revolute'>
      <pose relative_to='Revolve1'>-3.1375999999999999e-05 -0.058216999999999998 -0.23702999999999999 0 0 0</pose>
      <parent>Revolve1</parent>
      <child>Drive1</child>
      <axis>
        <xyz>0 1 0</xyz>
        <limit>
          <effort>50</effort>
          <velocity>20</velocity>
          <lower>-inf</lower>
          <upper>inf</upper>
        </limit>
        <dynamics>
          <spring_reference>0</spring_reference>
          <spring_stiffness>0</spring_stiffness>
        </dynamics>
      </axis>
    </joint>
    <link name='Drive1'>
      <pose relative_to='Joint_Drive1'>0 0 0 0 0 0</pose>
      <inertial>
        <pose>-0.000226014040947464 0.056913701454613698 -0.00041092617831861599 0 0 0</pose>
        <mass>0.63490888023754999</mass>
        <inertia>
          <ixx>0.00087557109023035098</ixx>
          <ixy>3.2832123413694501e-10</ixy>
          <ixz>3.82111291760209e-07</ixz>
          <iyy>0.0015701607684538599</iyy>
          <iyz>-1.8650894167025399e-10</iyz>
          <izz>0.00087610882947996205</izz>
        </inertia>
      </inertial>
      <collision name='Drive1_collision'>
        <pose>0 0 0 0 0 0</pose>
        <geometry>
          <mesh>
            <scale>1 1 1</scale>
            <uri>model://hermes_robot_description/meshes/Drive1.STL</uri>
          </mesh>
        </geometry>
      </collision>
      <visual name='Drive1_visual'>
        <pose>0 0 0 0 0 0</pose>
        <geometry>
          <mesh>
            <scale>1 1 1</scale>
            <uri>model://hermes_robot_description/meshes/Drive1.STL</uri>
          </mesh>
        </geometry>
        <material>
          <diffuse>0.990196109 1 1 1</diffuse>
          <ambient>0.990196109 1 1 1</ambient>
        </material>
      </visual>
    </link>
    <joint name='Joint_Revolve2' type='revolute'>
      <pose relative_to='base_footprint'>0.14248725309096799 -0.16236729901326299 0.080886521716585696 0 0 0</pose>
      <parent>base_footprint</parent>
      <child>Revolve2</child>
      <axis>
        <xyz>0 0 1</xyz>
        <limit>
          <effort>50</effort>
          <velocity>20</velocity>
          <lower>-inf</lower>
          <upper>inf</upper>
        </limit>
        <dynamics>
          <spring_reference>0</spring_reference>
          <spring_stiffness>0</spring_stiffness>
        </dynamics>
      </axis>
    </joint>
    <link name='Revolve2'>
      <pose relative_to='Joint_Revolve2'>0 0 0 0 0 0</pose>
      <inertial>
        <pose>0.000145747489205095 -0.0029324026431464798 -0.129541859145821 0 0 0</pose>
        <mass>0.35662956361492898</mass>
        <inertia>
          <ixx>0.0010117036184352599</ixx>
          <ixy>5.7579049219871001e-10</ixy>
          <ixz>3.1290994966966498e-07</ixz>
          <iyy>0.00086592654248545504</iyy>
          <iyz>4.8674230595362998e-08</iyz>
          <izz>0.000497931400463137</izz>
        </inertia>
      </inertial>
      <collision name='Revolve2_collision'>
        <pose>0 0 0 0 0 0</pose>
        <geometry>
          <mesh>
            <scale>1 1 1</scale>
            <uri>model://hermes_robot_description/meshes/Revolve2.STL</uri>
          </mesh>
        </geometry>
      </collision>
      <visual name='Revolve2_visual'>
        <pose>0 0 0 0 0 0</pose>
        <geometry>
          <mesh>
            <scale>1 1 1</scale>
            <uri>model://hermes_robot_description/meshes/Revolve2.STL</uri>
          </mesh>
        </geometry>
        <material>
          <diffuse>0.990196109 1 1 1</diffuse>
          <ambient>0.990196109 1 1 1</ambient>
        </material>
      </visual>
    </link>
    <joint name='Joint_Drive2' type='revolute'>
      <pose relative_to='Revolve2'>3.1375999999999999e-05 -0.061782999999999998 -0.23702999999999999 0 0 0</pose>
      <parent>Revolve2</parent>
      <child>Drive2</child>
      <axis>
        <xyz>0 1 0</xyz>
        <limit>
          <effort>50</effort>
          <velocity>20</velocity>
          <lower>-inf</lower>
          <upper>inf</upper>
        </limit>
        <dynamics>
          <spring_reference>0</spring_reference>
          <spring_stiffness>0</spring_stiffness>
        </dynamics>
      </axis>
    </joint>
    <link name='Drive2'>
      <pose relative_to='Joint_Drive2'>0 0 0 0 0 0</pose>
      <inertial>
        <pose>0.00022601404094738101 0.063086298545386305 -0.00041092617831864402 0 0 0</pose>
        <mass>0.63490888023755199</mass>
        <inertia>
          <ixx>0.00087557109023035304</ixx>
          <ixy>3.2832123462511201e-10</ixy>
          <ixz>-3.8211129176014902e-07</ixz>
          <iyy>0.0015701607684538599</iyy>
          <iyz>1.8650893926808301e-10</iyz>
          <izz>0.000876108829479964</izz>
        </inertia>
      </inertial>
      <collision name='Drive2_collision'>
        <pose>0 0 0 0 0 0</pose>
        <geometry>
          <mesh>
            <scale>1 1 1</scale>
            <uri>model://hermes_robot_description/meshes/Drive2.STL</uri>
          </mesh>
        </geometry>
      </collision>
      <visual name='Drive2_visual'>
        <pose>0 0 0 0 0 0</pose>
        <geometry>
          <mesh>
            <scale>1 1 1</scale>
            <uri>model://hermes_robot_description/meshes/Drive2.STL</uri>
          </mesh>
        </geometry>
        <material>
          <diffuse>0.990196109 1 1 1</diffuse>
          <ambient>0.990196109 1 1 1</ambient>
        </material>
      </visual>
    </link>
    <joint name='Joint_Revolve3' type='revolute'>
      <pose relative_to='base_footprint'>-0.14281274707469299 -0.16236729862735999 0.080886521716584905 0 0 0</pose>
      <parent>base_footprint</parent>
      <child>Revolve3</child>
      <axis>
        <xyz>0 0 1</xyz>
        <limit>
          <effort>50</effort>
          <velocity>20</velocity>
          <lower>-inf</lower>
          <upper>inf</upper>
        </limit>
        <dynamics>
          <spring_reference>0</spring_reference>
          <spring_stiffness>0</spring_stiffness>
        </dynamics>
      </axis>
    </joint>
    <link name='Revolve3'>
      <pose relative_to='Joint_Revolve3'>0 0 0 0 0 0</pose>
      <inertial>
        <pose>0.000145935393864483 -0.00330398152840003 -0.12936024168164101 0 0 0</pose>
        <mass>0.36061573342617598</mass>
        <inertia>
          <ixx>0.0010119801403592401</ixx>
          <ixy>5.7577951725919503e-10</ixy>
          <ixz>3.12909947056294e-07</ixz>
          <iyy>0.00086643890432855505</iyy>
          <iyz>4.8674094957309e-08</iyz>
          <izz>0.000498207922387442</izz>
        </inertia>
      </inertial>
      <collision name='Revolve3_collision'>
        <pose>0 0 0 0 0 0</pose>
        <geometry>
          <mesh>
            <scale>1 1 1</scale>
            <uri>model://hermes_robot_description/meshes/Revolve3.STL</uri>
          </mesh>
        </geometry>
      </collision>
      <visual name='Revolve3_visual'>
        <pose>0 0 0 0 0 0</pose>
        <geometry>
          <mesh>
            <scale>1 1 1</scale>
            <uri>model://hermes_robot_description/meshes/Revolve3.STL</uri>
          </mesh>
        </geometry>
        <material>
          <diffuse>0.990196109 1 1 1</diffuse>
          <ambient>0.990196109 1 1 1</ambient>
        </material>
      </visual>
    </link>
    <joint name='Joint_Drive3' type='revolute'>
      <pose relative_to='Revolve3'>3.1375999999999999e-05 -0.061782999999999998 -0.23702999999999999 0 0 0</pose>
      <parent>Revolve3</parent>
      <child>Drive3</child>
      <axis>
        <xyz>0 1 0</xyz>
        <limit>
          <effort>50</effort>
          <velocity>20</velocity>
          <lower>-inf</lower>
          <upper>inf</upper>
        </limit>
        <dynamics>
          <spring_reference>0</spring_reference>
          <spring_stiffness>0</spring_stiffness>
        </dynamics>
      </axis>
    </joint>
    <link name='Drive3'>
      <pose relative_to='Joint_Drive3'>0 0 0 0 0 0</pose>
      <inertial>
        <pose>0.000226014040947436 0.063086298545386305 -0.00041092617831855999 0 0 0</pose>
        <mass>0.63490888023755099</mass>
        <inertia>
          <ixx>0.00087557109023035098</ixx>
          <ixy>3.28321234455008e-10</ixy>
          <ixz>-3.8211129176064601e-07</ixz>
          <iyy>0.0015701607684538599</iyy>
          <iyz>1.8650893917522601e-10</iyz>
          <izz>0.00087610882947996302</izz>
        </inertia>
      </inertial>
      <collision name='Drive3_collision'>
        <pose>0 0 0 0 0 0</pose>
        <geometry>
          <mesh>
            <scale>1 1 1</scale>
            <uri>model://hermes_robot_description/meshes/Drive3.STL</uri>
          </mesh>
        </geometry>
      </collision>
      <visual name='Drive3_visual'>
        <pose>0 0 0 0 0 0</pose>
        <geometry>
          <mesh>
            <scale>1 1 1</scale>
            <uri>model://hermes_robot_description/meshes/Drive3.STL</uri>
          </mesh>
        </geometry>
        <material>
          <diffuse>0.990196109 1 1 1</diffuse>
          <ambient>0.990196109 1 1 1</ambient>
        </material>
      </visual>
    </link>
    <joint name='Joint_Revolve4' type='revolute'>
      <pose relative_to='base_footprint'>-0.14249000000000001 0.16236999999999999 0.080887000000000001 0 0 0</pose>
      <parent>base_footprint</parent>
      <child>Revolve4</child>
      <axis>
        <xyz>0 0 1</xyz>
        <limit>
          <effort>50</effort>
          <velocity>20</velocity>
          <lower>-inf</lower>
          <upper>inf</upper>
        </limit>
        <dynamics>
          <spring_reference>0</spring_reference>
          <spring_stiffness>0</spring_stiffness>
        </dynamics>
      </axis>
    </joint>
    <link name='Revolve4'>
      <pose relative_to='Joint_Revolve4'>0 0 0 0 0 0</pose>
      <inertial>
        <pose>-0.000145747489922687 0.0029324026433331899 -0.129541859145822 0 0 0</pose>
        <mass>0.35662956361492198</mass>
        <inertia>
          <ixx>0.0010117036184349099</ixx>
          <ixy>5.7578200415801398e-10</ixy>
          <ixz>-3.1290995035443299e-07</ixz>
          <iyy>0.000865926542485779</iyy>
          <iyz>-4.8674230584781803e-08</iyz>
          <izz>0.00049793140046312497</izz>
        </inertia>
      </inertial>
      <collision name='Revolve4_collision'>
        <pose>0 0 0 0 0 0</pose>
        <geometry>
          <mesh>
            <scale>1 1 1</scale>
            <uri>model://hermes_robot_description/meshes/Revolve4.STL</uri>
          </mesh>
        </geometry>
      </collision>
      <visual name='Revolve4_visual'>
        <pose>0 0 0 0 0 0</pose>
        <geometry>
          <mesh>
            <scale>1 1 1</scale>
            <uri>model://hermes_robot_description/meshes/Revolve4.STL</uri>
          </mesh>
        </geometry>
        <material>
          <diffuse>0.990196109 1 1 1</diffuse>
          <ambient>0.990196109 1 1 1</ambient>
        </material>
      </visual>
    </link>
    <joint name='Joint_Drive4' type='revolute'>
      <pose relative_to='Revolve4'>-3.1375912033032603e-05 -0.0582172989418 -0.23702760708766299 0 0 0</pose>
      <parent>Revolve4</parent>
      <child>Drive4</child>
      <axis>
        <xyz>0 1 0</xyz>
        <limit>
          <effort>50</effort>
          <velocity>20</velocity>
          <lower>-inf</lower>
          <upper>inf</upper>
        </limit>
        <dynamics>
          <spring_reference>0</spring_reference>
          <spring_stiffness>0</spring_stiffness>
        </dynamics>
      </axis>
    </joint>
    <link name='Drive4'>
      <pose relative_to='Joint_Drive4'>0 0 0 0 0 0</pose>
      <inertial>
        <pose>-0.00022055695320111199 0.060874693639427102 -0.00039463872270625899 0 0 0</pose>
        <mass>0.51681471822639102</mass>
        <inertia>
          <ixx>0.00077834232359823199</ixx>
          <ixy>-6.7958369150519099e-08</ixy>
          <ixz>1.91030313347439e-07</ixz>
          <iyy>0.0013949512000822699</iyy>
          <iyz>-1.3129681779691601e-07</iyz>
          <izz>0.000778611296294089</izz>
        </inertia>
      </inertial>
      <collision name='Drive4_collision'>
        <pose>0 0 0 0 0 0</pose>
        <geometry>
          <mesh>
            <scale>1 1 1</scale>
            <uri>model://hermes_robot_description/meshes/Drive4.STL</uri>
          </mesh>
        </geometry>
      </collision>
      <visual name='Drive4_visual'>
        <pose>0 0 0 0 0 0</pose>
        <geometry>
          <mesh>
            <scale>1 1 1</scale>
            <uri>model://hermes_robot_description/meshes/Drive4.STL</uri>
          </mesh>
        </geometry>
        <material>
          <diffuse>0.990196109 1 1 1</diffuse>
          <ambient>0.990196109 1 1 1</ambient>
        </material>
      </visual>
    </link>
    <frame name='base_footprint_joint' attached_to='base_footprint'>
      <pose>0 0 0 0 0 0</pose>
    </frame>
    <frame name='base_link' attached_to='base_footprint_joint'>
      <pose>0 0 0 0 0 0</pose>
    </frame>
    <frame name='CameraVisionJoint' attached_to='Camera_pivot'>
      <pose>-0.054499999999999597 0.0023070163905073398 -0.016858882862572599 3.14159265358979 0 3.14159265358979</pose>
    </frame>
    <frame name='CameraVision' attached_to='CameraVisionJoint'>
      <pose>0 0 0 0 0 0</pose>
    </frame>


    <!-- Additional Links to make the camera work -->

    <!-- A link that connects to the CameraVision frame to use for the sensor -->
    <link
      name='CameraVisionLink'>
      <pose relative_to='CameraVisionJoint'>0 0 0 0 0 0</pose>
      <inertial>
        <pose>0 0 0 0 0 0</pose>
        <mass>0.1</mass>
        <inertia>
          <ixx>0.0001</ixx>
          <ixy>0</ixy>
          <ixz>0</ixz>
          <iyy>0.0001</iyy>
          <iyz>0</iyz>
          <izz>0.0001</izz>
        </inertia>
      </inertial>
      <collision name='CameraVision_collision'>
        <pose>0 0 0 0 0 0</pose>
        <geometry>
          <box>
            <size>0.1 0.1 0.1</size>
          </box>
        </geometry>
      </collision>
      <visual name='CameraVision_visual'>
        <pose>0 0 0 0 0 0</pose>
        <geometry>
          <mesh>
            <scale>1 1 1</scale>
            <uri>model://hermes_robot_description/meshes/CameraVision.STL</uri>
          </mesh>
        </geometry>
        <material>
          <diffuse>0.5 0.5 0.5 1</diffuse>
          <ambient>0.5 0.5 0.5 1</ambient>
        </material>
      </visual>
      <sensor name="camera" type="camera">
        <pose>0 0 0 -1.57 -1.57 0</pose>
        <always_on>true</always_on>
        <topic>image_raw</topic>
        <update_rate>10</update_rate>
        <camera>
          <horizontal_fov>1.047</horizontal_fov>
          <image>
            <width>800</width>
            <height>600</height>
            <format>R8G8B8</format>
          </image>
          <clip>
            <near>0.1</near>
            <far>100</far>
          </clip>
        </camera>
      </sensor>

      <!-- Depth camera -->

      <sensor name="depth_camera" type="depth">
        <pose>0 0 0 -1.57 1.57 0</pose>
        <always_on>true</always_on>
        <update_rate>2</update_rate>
        <camera>
          <horizontal_fov>1.047</horizontal_fov>
          <image>
            <width>800</width>
            <height>600</height>
            <format>R8G8B8</format>
          </image>
          <clip>
            <near>0.1</near>
            <far>100</far>
          </clip>
        </camera>
      </sensor>

    </link>

    
    <!-- Make sure that this link is joined to the actual camera -->
    <joint name='Joint_Camera' type='fixed'>
      <pose relative_to='CameraVisionJoint'>0 0 0 0 0 0</pose>
      <parent>CameraVisionJoint</parent>
      <child>CameraVisionLink</child>
    </joint>


    <!-- ####################### Plugin Section ######################### -->

    <plugin
      filename="gz-sim-joint-state-publisher-system"
      name="gz::sim::systems::JointStatePublisher">
    </plugin>

    <plugin
      filename="gz-sim-pose-publisher-system"
      name="gz::sim::systems::PosePublisher">
      <publish_link_pose>true</publish_link_pose>
      <use_pose_vector_msg>true</use_pose_vector_msg>
      <static_publisher>true</static_publisher>
      <static_update_frequency>1</static_update_frequency>
    </plugin>

    <!--  Drive motor joint controllers -->
    <plugin
      filename="gz-sim-joint-position-controller-system"
      name="gz::sim::systems::JointPositionController">
      <joint_name>Joint_Drive1</joint_name>
      <topic>/drive/1/command</topic>
      <p_gain>1</p_gain>
      <i_gain>0.1</i_gain>
      <d_gain>0.01</d_gain>
      <i_max>1</i_max>
      <i_min>-1</i_min>
      <cmd_max>6.28</cmd_max>
      <cmd_min>-6.28</cmd_min>
    </plugin>

    <plugin
      filename="gz-sim-joint-position-controller-system"
      name="gz::sim::systems::JointPositionController">
      <topic>/drive/2/command</topic>
      <joint_name>Joint_Drive2</joint_name>
      <p_gain>1</p_gain>
      <i_gain>0.1</i_gain>
      <d_gain>0.01</d_gain>
      <i_max>1</i_max>
      <i_min>-1</i_min>
      <cmd_max>6.28</cmd_max>
      <cmd_min>-6.28</cmd_min>
    </plugin>

    <plugin
      filename="gz-sim-joint-position-controller-system"
      name="gz::sim::systems::JointPositionController">
      <joint_name>Joint_Drive3</joint_name>
      <topic>/drive/3/command</topic>
      <p_gain>1</p_gain>
      <i_gain>0.1</i_gain>
      <d_gain>0.01</d_gain>
      <i_max>1</i_max>
      <i_min>-1</i_min>
      <cmd_max>6.28</cmd_max>
      <cmd_min>-6.28</cmd_min>
    </plugin>

    <plugin
      filename="gz-sim-joint-position-controller-system"
      name="gz::sim::systems::JointPositionController">
      <joint_name>Joint_Drive4</joint_name>
      <topic>/drive/4/command</topic>
      <p_gain>1</p_gain>
      <i_gain>0.1</i_gain>
      <d_gain>0.01</d_gain>
      <i_max>1</i_max>
      <i_min>-1</i_min>
      <cmd_max>6.28</cmd_max>
      <cmd_min>-6.28</cmd_min>
    </plugin>

    <!-- Position Controllers -->

    <plugin
      filename="gz-sim-joint-position-controller-system"
      name="gz::sim::systems::JointPositionController">
      <joint_name>Joint_Revolve1</joint_name>
      <topic>/pivot/1/command</topic>
      <p_gain>1</p_gain>
      <i_gain>0.1</i_gain>
      <d_gain>0.01</d_gain>
      <i_max>1</i_max>
      <i_min>-1</i_min>
      <cmd_max>6.28</cmd_max>
      <cmd_min>-6.28</cmd_min>
    </plugin>

    <plugin
      filename="gz-sim-joint-position-controller-system"
      name="gz::sim::systems::JointPositionController">
      <topic>/pivot/2/command</topic>
      <joint_name>Joint_Revolve2</joint_name>
      <p_gain>1</p_gain>
      <i_gain>0.1</i_gain>
      <d_gain>0.01</d_gain>
      <i_max>1</i_max>
      <i_min>-1</i_min>
      <cmd_max>6.28</cmd_max>
      <cmd_min>-6.28</cmd_min>
    </plugin>

    <plugin
      filename="gz-sim-joint-position-controller-system"
      name="gz::sim::systems::JointPositionController">
      <joint_name>Joint_Revolve3</joint_name>
      <topic>/pivot/3/command</topic>
      <p_gain>1</p_gain>
      <i_gain>0.1</i_gain>
      <d_gain>0.01</d_gain>
      <i_max>1</i_max>
      <i_min>-1</i_min>
      <cmd_max>6.28</cmd_max>
      <cmd_min>-6.28</cmd_min>
    </plugin>

    <plugin
      filename="gz-sim-joint-position-controller-system"
      name="gz::sim::systems::JointPositionController">
      <joint_name>Joint_Revolve4</joint_name>
      <topic>/pivot/4/command</topic>
      <p_gain>1</p_gain>
      <i_gain>0.1</i_gain>
      <d_gain>0.01</d_gain>
      <i_max>1</i_max>
      <i_min>-1</i_min>
      <cmd_max>6.28</cmd_max>
      <cmd_min>-6.28</cmd_min>
    </plugin>

    <plugin
      filename="gz-sim-joint-position-controller-system"
      name="gz::sim::systems::JointPositionController">
      <joint_name>Camera_pivot_joint</joint_name>
      <topic>/camera/pivot/command</topic>
      <p_gain>1</p_gain>
      <i_gain>0.1</i_gain>
      <d_gain>0.01</d_gain>
      <i_max>1</i_max>
      <i_min>-1</i_min>
      <cmd_max>6.28</cmd_max>
      <cmd_min>-6.28</cmd_min>
    </plugin>

    <plugin filename="gz-sim-imu-system"
      name="gz::sim::systems::Imu">
    </plugin>
  </model>
</sdf>
