<?xml version="1.0" encoding="utf-8"?>
<!-- This URDF was automatically created by SolidWorks to URDF Exporter! Originally created by
Stephen Brawner (brawner@gmail.com) 
     Commit Version: 1.6.0-4-g7f85cfe  Build Version: 1.6.7995.38578
     For more information, please see http://wiki.ros.org/sw_urdf_exporter -->
<robot
  name="hermes_robot_description">
  <!-- Base Footprint -->
  <joint name="base_footprint_joint" type="fixed">
    <parent link="base_footprint" />
    <child link="base_link" />
    <origin xyz="0 0 0" rpy="0 0 0" />
  </joint>
  <link name="base_footprint">
  </link>
  <!-- End of Base Footprint -->
  <link
    name="base_link">
    <inertial>
      <origin
        xyz="7.96027345322404E-06 0.00267876360260728 0.0437561412092237"
        rpy="0 0 0" />
      <mass
        value="5.83594079476047" />
      <inertia
        ixx="0.0262320539772903"
        ixy="2.83128720780491E-06"
        ixz="1.72796857650756E-08"
        iyy="0.0221066349182729"
        iyz="9.51545100183853E-09"
        izz="0.0463251880864419" />
    </inertial>
    <visual>
      <origin
        xyz="0 0 0"
        rpy="0 0 0" />
      <geometry>
        <mesh
          filename="package://hermes_robot_description/meshes/base_link.STL" />
      </geometry>
      <material
        name="">
        <color
          rgba="0.792156862745098 0.819607843137255 0.933333333333333 1" />
      </material>
    </visual>
    <collision>
      <origin
        xyz="0 0 0"
        rpy="0 0 0" />
      <geometry>
        <mesh
          filename="package://hermes_robot_description/meshes/base_link.STL" />
      </geometry>
    </collision>
  </link>
  <link
    name="Revolve1">
    <inertial>
      <origin
        xyz="-0.00330526162854908 -0.000113326386827706 -0.12936024003018"
        rpy="0 0 0" />
      <mass
        value="0.360615727575473" />
      <inertia
        ixx="0.000866448995447055"
        ixy="1.43445064537622E-06"
        ixz="4.46493221125416E-08"
        iyy="0.0010119628351452"
        iyz="-3.11537804771866E-07"
        izz="0.000498205901651864" />
    </inertial>
    <visual>
      <origin
        xyz="0 0 0"
        rpy="0 0 0" />
      <geometry>
        <mesh
          filename="package://hermes_robot_description/meshes/Revolve1.STL" />
      </geometry>
      <material
        name="">
        <color
          rgba="0.792156862745098 0.819607843137255 0.933333333333333 1" />
      </material>
    </visual>
    <collision>
      <origin
        xyz="0 0 0"
        rpy="0 0 0" />
      <geometry>
        <mesh
          filename="package://hermes_robot_description/meshes/Revolve1.STL" />
      </geometry>
    </collision>
  </link>
  <joint
    name="Joint_Revolve1"
    type="continuous">
    <origin
      xyz="0.14293 0.16281 0.080887"
      rpy="0 0 0" />
    <parent
      link="base_link" />
    <child
      link="Revolve1" />
    <axis
      xyz="0 0 -1" />
    <limit
      lower="-6.28"
      upper="6.28"
      effort="50"
      velocity="20" />
  </joint>
  <link
    name="Drive1">
    <inertial>
      <origin
        xyz="-0.0569131612299077 0.000335522483649792 -0.000410926164939512"
        rpy="0 0 0" />
      <mass
        value="0.63490886843573" />
      <inertia
        ixx="0.00157009314369376"
        ixy="-6.85299738088303E-06"
        ixz="3.95514016843013E-09"
        iyy="0.000875638707740947"
        iyz="3.82089458087413E-07"
        izz="0.000876108825829738" />
    </inertial>
    <visual>
      <origin
        xyz="0 0 0"
        rpy="0 0 0" />
      <geometry>
        <mesh
          filename="package://hermes_robot_description/meshes/Drive1.STL" />
      </geometry>
      <material
        name="">
        <color
          rgba="0.792156862745098 0.819607843137255 0.933333333333333 1" />
      </material>
    </visual>
    <collision>
      <origin
        xyz="0 0 0"
        rpy="0 0 0" />
      <geometry>
        <mesh
          filename="package://hermes_robot_description/meshes/Drive1.STL" />
      </geometry>
    </collision>
  </link>
  <joint
    name="Joint_Drive1"
    type="continuous">
    <origin
      xyz="0.058214 -0.00060576 -0.23703"
      rpy="0 0 0" />
    <parent
      link="Revolve1" />
    <child
      link="Drive1" />
    <axis
      xyz="-0.99995 0.0098663 0" />
    <limit
      lower="0"
      upper="0"
      effort="50"
      velocity="20" />
  </joint>
  <link
    name="Revolve2">
    <inertial>
      <origin
        xyz="0.00293343302999416 0.000123773024353679 -0.129541857886687"
        rpy="0 0 0" />
      <mass
        value="0.35662955912804" />
      <inertia
        ixx="0.000865930640437375"
        ixy="1.09063403993617E-06"
        ixz="-4.53834609389432E-08"
        iyy="0.00101169229109942"
        iyz="3.11434171867246E-07"
        izz="0.000497929383773699" />
    </inertial>
    <visual>
      <origin
        xyz="0 0 0"
        rpy="0 0 0" />
      <geometry>
        <mesh
          filename="package://hermes_robot_description/meshes/Revolve2.STL" />
      </geometry>
      <material
        name="">
        <color
          rgba="0.792156862745098 0.819607843137255 0.933333333333333 1" />
      </material>
    </visual>
    <collision>
      <origin
        xyz="0 0 0"
        rpy="0 0 0" />
      <geometry>
        <mesh
          filename="package://hermes_robot_description/meshes/Revolve2.STL" />
      </geometry>
    </collision>
  </link>
  <joint
    name="Joint_Revolve2"
    type="continuous">
    <origin
      xyz="0.14237 -0.16281 0.080887"
      rpy="0 0 0" />
    <parent
      link="base_link" />
    <child
      link="Revolve2" />
    <axis
      xyz="0 0 -1" />
    <limit
      lower="-6.28"
      upper="6.28"
      effort="50"
      velocity="20" />
  </joint>
  <link
    name="Drive2">
    <inertial>
      <origin
        xyz="-0.0630828349978768 0.000698623255382169 -0.000410926168290859"
        rpy="0 0 0" />
      <mass
        value="0.634908871563249" />
      <inertia
        ixx="0.00157012177717613"
        ixy="-5.20374912355723E-06"
        ixz="-3.04809767475515E-09"
        iyy="0.000875610076231738"
        iyz="-3.8209811580205E-07"
        izz="0.000876108826794846" />
    </inertial>
    <visual>
      <origin
        xyz="0 0 0"
        rpy="0 0 0" />
      <geometry>
        <mesh
          filename="package://hermes_robot_description/meshes/Drive2.STL" />
      </geometry>
      <material
        name="">
        <color
          rgba="0.792156862745098 0.819607843137255 0.933333333333333 1" />
      </material>
    </visual>
    <collision>
      <origin
        xyz="0 0 0"
        rpy="0 0 0" />
      <geometry>
        <mesh
          filename="package://hermes_robot_description/meshes/Drive2.STL" />
      </geometry>
    </collision>
  </link>
  <joint
    name="Joint_Drive2"
    type="continuous">
    <origin
      xyz="0.0617812221879258 -0.000431473668773497 -0.237027607087667"
      rpy="0 0 0" />
    <parent
      link="Revolve2" />
    <child
      link="Drive2" />
    <axis
      xyz="-1 0 0" />
    <limit
      lower="0"
      upper="0"
      effort="50"
      velocity="20" />
  </joint>
  <link
    name="Revolve3">
    <inertial>
      <origin
        xyz="-0.00327313554520364 -0.000473427489680461 -0.129360249577479"
        rpy="0 0 0" />
      <mass
        value="0.360615750151738" />
      <inertia
        ixx="0.000867871006099278"
        ixy="-1.43872672154306E-05"
        ixz="7.82144171103749E-08"
        iyy="0.00101054062876924"
        iyz="-3.04975648895368E-07"
        izz="0.000498206051923298" />
    </inertial>
    <visual>
      <origin
        xyz="0 0 0"
        rpy="0 0 0" />
      <geometry>
        <mesh
          filename="package://hermes_robot_description/meshes/Revolve3.STL" />
      </geometry>
      <material
        name="">
        <color
          rgba="0.792156862745098 0.819607843137255 0.933333333333333 1" />
      </material>
    </visual>
    <collision>
      <origin
        xyz="0 0 0"
        rpy="0 0 0" />
      <geometry>
        <mesh
          filename="package://hermes_robot_description/meshes/Revolve3.STL" />
      </geometry>
    </collision>
  </link>
  <joint
    name="Joint_Revolve3"
    type="continuous">
    <origin
      xyz="-0.14238 -0.16246 0.080887"
      rpy="0 0 0" />
    <parent
      link="base_link" />
    <child
      link="Revolve3" />
    <axis
      xyz="0 0 -1" />
    <limit
      lower="-6.28"
      upper="6.28"
      effort="50"
      velocity="20" />
  </joint>
  <link
    name="Drive3">
    <inertial>
      <origin
        xyz="0.0627967378941705 0.00604167341527931 -0.000410929725528447"
        rpy="0 0 0" />
      <mass
        value="0.634908725633114" />
      <inertia
        ixx="0.00156330709888045"
        ixy="6.86543308803907E-05"
        ixz="-3.77732992474278E-08"
        iyy="0.000882424512726853"
        iyz="3.80286982168367E-07"
        izz="0.000876108783202714" />
    </inertial>
    <visual>
      <origin
        xyz="0 0 0"
        rpy="0 0 0" />
      <geometry>
        <mesh
          filename="package://hermes_robot_description/meshes/Drive3.STL" />
      </geometry>
      <material
        name="">
        <color
          rgba="0.792156862745098 0.819607843137255 0.933333333333333 1" />
      </material>
    </visual>
    <collision>
      <origin
        xyz="0 0 0"
        rpy="0 0 0" />
      <geometry>
        <mesh
          filename="package://hermes_robot_description/meshes/Drive3.STL" />
      </geometry>
    </collision>
  </link>
  <joint
    name="Joint_Drive3"
    type="continuous">
    <origin
      xyz="-0.0614740204971197 -0.0061683010963027 -0.237027607087665"
      rpy="0 0 0" />
    <parent
      link="Revolve3" />
    <child
      link="Drive3" />
    <axis
      xyz="-0.995054216106331 -0.0993333126851991 0" />
    <limit
      lower="0"
      upper="0"
      effort="50"
      velocity="20" />
  </joint>
  <link
    name="Revolve4">
    <inertial>
      <origin
        xyz="-0.00292246160250009 -0.00028181299162458 -0.129541866870304"
        rpy="0 0 0" />
      <mass
        value="0.356629579543393" />
      <inertia
        ixx="0.000866240775757233"
        ixy="-6.76451472739006E-06"
        ixz="6.29978268598607E-08"
        iyy="0.00101138894722501"
        iyz="-3.10359338661498E-07"
        izz="0.000497931449955283" />
    </inertial>
    <visual>
      <origin
        xyz="0 0 0"
        rpy="0 0 0" />
      <geometry>
        <mesh
          filename="package://hermes_robot_description/meshes/Revolve4.STL" />
      </geometry>
      <material
        name="">
        <color
          rgba="0.792156862745098 0.819607843137255 0.933333333333333 1" />
      </material>
    </visual>
    <collision>
      <origin
        xyz="0 0 0"
        rpy="0 0 0" />
      <geometry>
        <mesh
          filename="package://hermes_robot_description/meshes/Revolve4.STL" />
      </geometry>
    </collision>
  </link>
  <joint
    name="Joint_Revolve4"
    type="continuous">
    <origin
      xyz="-0.14238 0.16283 0.080887"
      rpy="0 0 0" />
    <parent
      link="base_link" />
    <child
      link="Revolve4" />
    <axis
      xyz="0 0 -1" />
    <limit
      lower="-6.28"
      upper="6.28"
      effort="50"
      velocity="20" />
  </joint>
  <link
    name="Drive4">
    <inertial>
      <origin
        xyz="-0.0607987445014714 -0.00304784974714295 -0.000394638531493491"
        rpy="0 0 0" />
      <mass
        value="0.516814674773903" />
      <inertia
        ixx="0.00139361456190444"
        ixy="2.86772411327649E-05"
        ixz="1.22281649358375E-07"
        iyy="0.0007796789234529"
        iyz="1.96927193653209E-07"
        izz="0.000778611280137647" />
    </inertial>
    <visual>
      <origin
        xyz="0 0 0"
        rpy="0 0 0" />
      <geometry>
        <mesh
          filename="package://hermes_robot_description/meshes/Drive4.STL" />
      </geometry>
      <material
        name="">
        <color
          rgba="0.792156862745098 0.819607843137255 0.933333333333333 1" />
      </material>
    </visual>
    <collision>
      <origin
        xyz="0 0 0"
        rpy="0 0 0" />
      <geometry>
        <mesh
          filename="package://hermes_robot_description/meshes/Drive4.STL" />
      </geometry>
    </collision>
  </link>
  <joint
    name="Joint_Drive4"
    type="continuous">
    <origin
      xyz="0.0581559218672338 0.00267275743362028 -0.237027607087664"
      rpy="0 0 0" />
    <parent
      link="Revolve4" />
    <child
      link="Drive4" />
    <axis
      xyz="-0.998920691338622 -0.0464483844236803 0" />
    <limit
      lower="0"
      upper="0"
      effort="50"
      velocity="20" />
  </joint>
  <link
    name="Camera_pivot">
    <inertial>
      <origin
        xyz="-0.0555938848411197 0.000418614354003276 -0.00327348513176728"
        rpy="0 0 0" />
      <mass
        value="1.2878670523968" />
      <inertia
        ixx="0.000117585935949458"
        ixy="-1.49741441165642E-06"
        ixz="1.12423158524668E-05"
        iyy="0.000794899141050403"
        iyz="7.61075263134137E-07"
        izz="0.000787886593810218" />
    </inertial>
    <visual>
      <origin
        xyz="0 0 0"
        rpy="0 0 0" />
      <geometry>
        <mesh
          filename="package://hermes_robot_description/meshes/Camera_pivot.STL" />
      </geometry>
      <material
        name="">
        <color
          rgba="0.792156862745098 0.819607843137255 0.933333333333333 1" />
      </material>
    </visual>
    <collision>
      <origin
        xyz="0 0 0"
        rpy="0 0 0" />
      <geometry>
        <mesh
          filename="package://hermes_robot_description/meshes/Camera_pivot.STL" />
      </geometry>
    </collision>
  </link>
  <joint
    name="Camera_pivot_joint"
    type="revolute">
    <origin
      xyz="0.0543500000000001 0.230150000000001 0.0600000000000003"
      rpy="1.5707963267949 0 0" />
    <parent
      link="base_link" />
    <child
      link="Camera_pivot" />
    <axis
      xyz="1 0 0" />
    <limit
      lower="0"
      upper="0"
      effort="20"
      velocity="10" />
  </joint>
  <link
    name="CameraVision">
    <inertial>
      <origin
        xyz="-3.83265467973626E-17 -6.77896212537346E-05 -0.000495383252896442"
        rpy="0 0 0" />
      <mass
        value="0.00122306679751053" />
      <inertia
        ixx="2.45260777746173E-08"
        ixy="1.49835825799552E-22"
        ixz="-7.43449114089117E-22"
        iyy="6.15023324061755E-07"
        iyz="3.26714169017072E-09"
        izz="6.38451387870187E-07" />
    </inertial>
    <visual>
      <origin
        xyz="0 0 0"
        rpy="0 0 0" />
      <geometry>
        <mesh
          filename="package://hermes_robot_description/meshes/CameraVision.STL" />
      </geometry>
      <material
        name="">
        <color
          rgba="0.792156862745098 0.819607843137255 0.933333333333333 1" />
      </material>
    </visual>
    <collision>
      <origin
        xyz="0 0 0"
        rpy="0 0 0" />
      <geometry>
        <mesh
          filename="package://hermes_robot_description/meshes/CameraVision.STL" />
      </geometry>
    </collision>
  </link>
  <joint
    name="CameraVisionJoint"
    type="fixed">
    <origin
      xyz="-0.0544999999999996 0.00230701639050734 -0.0168588828625726"
      rpy="3.14159265358979 0 3.14159265358979" />
    <parent
      link="Camera_pivot" />
    <child
      link="CameraVision" />
    <axis
      xyz="0 0 0" />
    <limit
      effort="20"
      velocity="10" />
  </joint>
</robot>