<?xml version="1.0" encoding="utf-8"?>
<!-- This URDF was automatically created by SolidWorks to URDF Exporter! Originally created by Stephen Brawner (brawner@gmail.com) 
     Commit Version: 1.6.0-4-g7f85cfe  Build Version: 1.6.7995.38578
     For more information, please see http://wiki.ros.org/sw_urdf_exporter -->
<robot
  name="Assem1.SLDASM">
  <link
    name="base_link">
    <inertial>
      <origin
        xyz="-1.80122982527309E-05 0.00268113709179614 0.0437561412092237"
        rpy="0 0 0" />
      <mass
        value="5.83594079476047" />
      <inertia
        ixx="0.0262320570286846"
        ixy="2.82877643144792E-06"
        ixz="1.51090613026226E-09"
        iyy="0.0221066318668786"
        iyz="1.64817571323087E-09"
        izz="0.0463251880864419" />
    </inertial>
    <visual>
      <origin
        xyz="0 0 0"
        rpy="0 0 0" />
      <geometry>
        <mesh
          filename="package://Assem1.SLDASM/meshes/base_link.STL" />
      </geometry>
      <material
        name="">
        <color
          rgba="0.792156862745098 0.819607843137255 0.933333333333333 1" />
      </material>
    </visual>
    <collision>
      <origin
        xyz="0 0 0"
        rpy="0 0 0" />
      <geometry>
        <mesh
          filename="package://Assem1.SLDASM/meshes/base_link.STL" />
      </geometry>
    </collision>
  </link>
  <link
    name="Revolve1">
    <inertial>
      <origin
        xyz="-0.00203157253473932 -3.3257002236553E-06 -0.146515511784745"
        rpy="0 0 0" />
      <mass
        value="0.26996802034521" />
      <inertia
        ixx="0.000817081008544826"
        ixy="1.43755452488312E-06"
        ixz="5.94712654175265E-08"
        iyy="0.000962909407158132"
        iyz="1.19067342375248E-06"
        izz="0.000432508914878457" />
    </inertial>
    <visual>
      <origin
        xyz="0 0 0"
        rpy="0 0 0" />
      <geometry>
        <mesh
          filename="package://Assem1.SLDASM/meshes/Revolve1.STL" />
      </geometry>
      <material
        name="">
        <color
          rgba="0.792156862745098 0.819607843137255 0.933333333333333 1" />
      </material>
    </visual>
    <collision>
      <origin
        xyz="0 0 0"
        rpy="0 0 0" />
      <geometry>
        <mesh
          filename="package://Assem1.SLDASM/meshes/Revolve1.STL" />
      </geometry>
    </collision>
  </link>
  <joint
    name="Joint_Revolve1"
    type="continuous">
    <origin
      xyz="0.142934293002077 0.162809949770145 0.0808865217165859"
      rpy="0 0 0" />
    <parent
      link="base_link" />
    <child
      link="Revolve1" />
    <axis
      xyz="0 0 -1" />
    <limit
      lower="0"
      upper="0"
      effort="0"
      velocity="0" />
  </joint>
  <link
    name="Drive1">
    <inertial>
      <origin
        xyz="-0.0595900865520644 0.00103045575495944 0.000120396514376397"
        rpy="0 0 0" />
      <mass
        value="0.968781681350827" />
      <inertia
        ixx="0.00433308692834699"
        ixy="-1.99069564081483E-05"
        ixz="1.18928999632542E-07"
        iyy="0.0023145060676988"
        iyz="-8.12871262199869E-08"
        izz="0.00231372917988357" />
    </inertial>
    <visual>
      <origin
        xyz="0 0 0"
        rpy="0 0 0" />
      <geometry>
        <mesh
          filename="package://Assem1.SLDASM/meshes/Drive1.STL" />
      </geometry>
      <material
        name="">
        <color
          rgba="0.792156862745098 0.819607843137255 0.933333333333333 1" />
      </material>
    </visual>
    <collision>
      <origin
        xyz="0 0 0"
        rpy="0 0 0" />
      <geometry>
        <mesh
          filename="package://Assem1.SLDASM/meshes/Drive1.STL" />
      </geometry>
    </collision>
  </link>
  <joint
    name="Joint_Drive1"
    type="continuous">
    <origin
      xyz="0.0582113596874176 -0.000889147356134073 -0.237077064343304"
      rpy="0 0 0" />
    <parent
      link="Revolve1" />
    <child
      link="Drive1" />
    <axis
      xyz="-0.999951327239453 0.0098662633279638 0" />
    <limit
      lower="0"
      upper="0"
      effort="0"
      velocity="0" />
  </joint>
  <link
    name="Revolve2">
    <inertial>
      <origin
        xyz="0.00369564587521401 9.94381063517957E-05 -0.14554695452501"
        rpy="0 0 0" />
      <mass
        value="0.278169943270249" />
      <inertia
        ixx="0.000818393002551496"
        ixy="1.0906620321178E-06"
        ixz="-4.70925775856809E-08"
        iyy="0.000964158396336435"
        iyz="8.330325220129E-08"
        izz="0.000433636015059848" />
    </inertial>
    <visual>
      <origin
        xyz="0 0 0"
        rpy="0 0 0" />
      <geometry>
        <mesh
          filename="package://Assem1.SLDASM/meshes/Revolve2.STL" />
      </geometry>
      <material
        name="">
        <color
          rgba="0.792156862745098 0.819607843137255 0.933333333333333 1" />
      </material>
    </visual>
    <collision>
      <origin
        xyz="0 0 0"
        rpy="0 0 0" />
      <geometry>
        <mesh
          filename="package://Assem1.SLDASM/meshes/Revolve2.STL" />
      </geometry>
    </collision>
  </link>
  <joint
    name="Joint_Revolve2"
    type="continuous">
    <origin
      xyz="0.142366067810622 -0.162810625283319 0.0808865217165886"
      rpy="0 0 0" />
    <parent
      link="base_link" />
    <child
      link="Revolve2" />
    <axis
      xyz="0 0 -1" />
    <limit
      lower="0"
      upper="0"
      effort="0"
      velocity="0" />
  </joint>
  <link
    name="Drive2">
    <inertial>
      <origin
        xyz="-0.0604042563748639 1.00501994926006E-05 0.000120396499160763"
        rpy="0 0 0" />
      <mass
        value="0.968781685280358" />
      <inertia
        ixx="0.00433317009545423"
        ixy="-1.51130610426148E-05"
        ixz="-1.19121259095147E-07"
        iyy="0.00231442290382323"
        iyz="8.10046961055835E-08"
        izz="0.00231372918105276" />
    </inertial>
    <visual>
      <origin
        xyz="0 0 0"
        rpy="0 0 0" />
      <geometry>
        <mesh
          filename="package://Assem1.SLDASM/meshes/Drive2.STL" />
      </geometry>
      <material
        name="">
        <color
          rgba="0.792156862745098 0.819607843137255 0.933333333333333 1" />
      </material>
    </visual>
    <collision>
      <origin
        xyz="0 0 0"
        rpy="0 0 0" />
      <geometry>
        <mesh
          filename="package://Assem1.SLDASM/meshes/Drive2.STL" />
      </geometry>
    </collision>
  </link>
  <joint
    name="Joint_Drive2"
    type="continuous">
    <origin
      xyz="0.0617833347446545 -0.000148083201917115 -0.237077064343308"
      rpy="0 0 0" />
    <parent
      link="Revolve2" />
    <child
      link="Drive2" />
    <axis
      xyz="0.999971937783406 -0.00749157164416232 0" />
    <limit
      lower="0"
      upper="0"
      effort="0"
      velocity="0" />
  </joint>
  <link
    name="Revolve3">
    <inertial>
      <origin
        xyz="-0.145078348740283 0.000298264757163519 -0.00416215996009126"
        rpy="0 0 0" />
      <mass
        value="0.282156111545984" />
      <inertia
        ixx="0.000434125726646059"
        ixy="2.26740392878708E-06"
        ixz="2.46147953855087E-08"
        iyy="0.000964214819932212"
        iyz="-1.47963647126638E-06"
        izz="0.000818912285874927" />
    </inertial>
    <visual>
      <origin
        xyz="0 0 0"
        rpy="0 0 0" />
      <geometry>
        <mesh
          filename="package://Assem1.SLDASM/meshes/Revolve3.STL" />
      </geometry>
      <material
        name="">
        <color
          rgba="0.792156862745098 0.819607843137255 0.933333333333333 1" />
      </material>
    </visual>
    <collision>
      <origin
        xyz="0 0 0"
        rpy="0 0 0" />
      <geometry>
        <mesh
          filename="package://Assem1.SLDASM/meshes/Revolve3.STL" />
      </geometry>
    </collision>
  </link>
  <joint
    name="Joint_Revolve3"
    type="continuous">
    <origin
      xyz="-0.142934337601559 -0.162809870489869 0.0808865217165859"
      rpy="3.14159265358979 -1.5707963267949 0" />
    <parent
      link="base_link" />
    <child
      link="Revolve3" />
    <axis
      xyz="-1 0 0" />
    <limit
      lower="0"
      upper="0"
      effort="0"
      velocity="0" />
  </joint>
  <link
    name="Drive3">
    <inertial>
      <origin
        xyz="0.00012039651646828 0.000173152781060726 0.0604040240679212"
        rpy="0 0 0" />
      <mass
        value="0.968781680813742" />
      <inertia
        ixx="0.00231372917972381"
        ixy="8.13257654301477E-08"
        ixz="1.1890262017798E-07"
        iyy="0.00231451922820414"
        iyz="2.05633802827414E-05"
        izz="0.00433307376740015" />
    </inertial>
    <visual>
      <origin
        xyz="0 0 0"
        rpy="0 0 0" />
      <geometry>
        <mesh
          filename="package://Assem1.SLDASM/meshes/Drive3.STL" />
      </geometry>
      <material
        name="">
        <color
          rgba="0.792156862745098 0.819607843137255 0.933333333333333 1" />
      </material>
    </visual>
    <collision>
      <origin
        xyz="0 0 0"
        rpy="0 0 0" />
      <geometry>
        <mesh
          filename="package://Assem1.SLDASM/meshes/Drive3.STL" />
      </geometry>
    </collision>
  </link>
  <joint
    name="Joint_Drive3"
    type="continuous">
    <origin
      xyz="-0.237077064343304 -0.000314896345636445 -0.0617826975095977"
      rpy="0 0 0" />
    <parent
      link="Revolve3" />
    <child
      link="Drive3" />
    <axis
      xyz="0 -0.0101914398562096 -0.999948065928255" />
    <limit
      lower="0"
      upper="0"
      effort="0"
      velocity="0" />
  </joint>
  <link
    name="Revolve4">
    <inertial>
      <origin
        xyz="-0.00369447983778617 -5.57141729288224E-05 -0.145545341192344"
        rpy="0 0 0" />
      <mass
        value="0.278169949354846" />
      <inertia
        ixx="0.000818395728366805"
        ixy="-1.00119769955746E-06"
        ixz="4.24905936666421E-08"
        iyy="0.000964130017408441"
        iyz="8.9761506571256E-07"
        izz="0.000433670847908861" />
    </inertial>
    <visual>
      <origin
        xyz="0 0 0"
        rpy="0 0 0" />
      <geometry>
        <mesh
          filename="package://Assem1.SLDASM/meshes/Revolve4.STL" />
      </geometry>
      <material
        name="">
        <color
          rgba="0.792156862745098 0.819607843137255 0.933333333333333 1" />
      </material>
    </visual>
    <collision>
      <origin
        xyz="0 0 0"
        rpy="0 0 0" />
      <geometry>
        <mesh
          filename="package://Assem1.SLDASM/meshes/Revolve4.STL" />
      </geometry>
    </collision>
  </link>
  <joint
    name="Joint_Revolve4"
    type="continuous">
    <origin
      xyz="-0.14236842293664 0.162814683931788 0.0808865217165862"
      rpy="0 0 0" />
    <parent
      link="base_link" />
    <child
      link="Revolve4" />
    <axis
      xyz="0 0 -1" />
    <limit
      lower="0"
      upper="0"
      effort="0"
      velocity="0" />
  </joint>
  <link
    name="Drive4">
    <inertial>
      <origin
        xyz="-0.0622112205431674 4.79255844326731E-06 0.000114732036940929"
        rpy="0 0 0" />
      <mass
        value="0.850687527986547" />
      <inertia
        ixx="0.00415798393864942"
        ixy="1.31982957892881E-05"
        ixz="7.75917649713274E-08"
        iyy="0.00221684368675787"
        iyz="-2.11694871406755E-07"
        izz="0.00221655869094812" />
    </inertial>
    <visual>
      <origin
        xyz="0 0 0"
        rpy="0 0 0" />
      <geometry>
        <mesh
          filename="package://Assem1.SLDASM/meshes/Drive4.STL" />
      </geometry>
      <material
        name="">
        <color
          rgba="0.792156862745098 0.819607843137255 0.933333333333333 1" />
      </material>
    </visual>
    <collision>
      <origin
        xyz="0 0 0"
        rpy="0 0 0" />
      <geometry>
        <mesh
          filename="package://Assem1.SLDASM/meshes/Drive4.STL" />
      </geometry>
    </collision>
  </link>
  <joint
    name="Joint_Drive4"
    type="continuous">
    <origin
      xyz="0.0582180879812486 8.49204713872509E-05 -0.237077064343304"
      rpy="0 0 0" />
    <parent
      link="Revolve4" />
    <child
      link="Drive4" />
    <axis
      xyz="-0.999976432452814 -0.00686545984934792 0" />
    <limit
      lower="0"
      upper="0"
      effort="0"
      velocity="0" />
  </joint>
  <link
    name="Camera_pivot">
    <inertial>
      <origin
        xyz="-0.0555938677541015 -0.000242330848978831 -0.00329123732557138"
        rpy="0 0 0" />
      <mass
        value="1.28786623127725" />
      <inertia
        ixx="0.000117585603142808"
        ixy="7.73537803843833E-07"
        ixz="1.1315000572726E-05"
        iyy="0.00079491757869897"
        iyz="-6.69201512905299E-07"
        izz="0.000787867424546528" />
    </inertial>
    <visual>
      <origin
        xyz="0 0 0"
        rpy="0 0 0" />
      <geometry>
        <mesh
          filename="package://Assem1.SLDASM/meshes/Camera_pivot.STL" />
      </geometry>
      <material
        name="">
        <color
          rgba="0.792156862745098 0.819607843137255 0.933333333333333 1" />
      </material>
    </visual>
    <collision>
      <origin
        xyz="0 0 0"
        rpy="0 0 0" />
      <geometry>
        <mesh
          filename="package://Assem1.SLDASM/meshes/Camera_pivot.STL" />
      </geometry>
    </collision>
  </link>
  <joint
    name="Camera_pivot"
    type="revolute">
    <origin
      xyz="0.05435 0.23015 0.06"
      rpy="1.5708 0 0" />
    <parent
      link="base_link" />
    <child
      link="Camera_pivot" />
    <axis
      xyz="1 0 0" />
    <limit
      lower="0"
      upper="0"
      effort="0"
      velocity="0" />
  </joint>
</robot>